2023-11-21 13:23:04,024 - root - INFO - Initiating present weather
2023-11-21 13:23:04,028 - urllib3.connectionpool - DEBUG - Starting new HTTPS connection (1): radar.bmkg.go.id:8060
2023-11-21 13:23:04,101 - urllib3.connectionpool - DEBUG - https://radar.bmkg.go.id:8060 "GET /getRadarGeotif?token=19387e71e78522ae4172ec0fda640983b8438c9cfa0ca571623cb69d8327&radar=amandemenForecast&type=latest HTTP/1.1" 200 90
2023-11-21 13:23:04,104 - rasterio.env - DEBUG - Entering env context: <rasterio.env.Env object at 0x7fb9be64a390>
2023-11-21 13:23:04,105 - rasterio.env - DEBUG - Starting outermost env
2023-11-21 13:23:04,105 - rasterio.env - DEBUG - No GDAL environment exists
2023-11-21 13:23:04,105 - rasterio.env - DEBUG - New GDAL environment <rasterio._env.GDALEnv object at 0x7fb9be64a3e0> created
2023-11-21 13:23:04,109 - rasterio._filepath - DEBUG - Installing FilePath filesystem handler plugin...
2023-11-21 13:23:04,110 - rasterio._env - DEBUG - GDAL data found in package: path='/home/swx/miniconda3/envs/present_weather/lib/python3.12/site-packages/rasterio/gdal_data'.
2023-11-21 13:23:04,110 - rasterio._env - DEBUG - PROJ_LIB found in environment.
2023-11-21 13:23:04,110 - rasterio._env - DEBUG - Started GDALEnv: self=<rasterio._env.GDALEnv object at 0x7fb9be64a3e0>.
2023-11-21 13:23:04,110 - rasterio.env - DEBUG - Entered env context: <rasterio.env.Env object at 0x7fb9be64a390>
2023-11-21 13:23:04,110 - rasterio._base - DEBUG - Sharing flag: 0
2023-11-21 13:23:04,304 - rasterio._base - DEBUG - Nodata success: 1, Nodata value: nan
2023-11-21 13:23:04,304 - rasterio._base - DEBUG - Dataset <open DatasetReader name='https://radar.bmkg.go.id/raster/radarsatelit_202311211150.tif' mode='r'> is started.
2023-11-21 13:23:04,304 - rasterio.env - DEBUG - Exiting env context: <rasterio.env.Env object at 0x7fb9be64a390>
2023-11-21 13:23:04,304 - rasterio.env - DEBUG - Cleared existing <rasterio._env.GDALEnv object at 0x7fb9be64a3e0> options
2023-11-21 13:23:04,305 - rasterio._env - DEBUG - Stopped GDALEnv <rasterio._env.GDALEnv object at 0x7fb9be64a3e0>.
2023-11-21 13:23:04,305 - rasterio.env - DEBUG - Exiting outermost env
2023-11-21 13:23:04,305 - rasterio.env - DEBUG - Exited env context: <rasterio.env.Env object at 0x7fb9be64a390>
2023-11-21 13:23:04,305 - rasterio.env - DEBUG - Entering env context: <rasterio.env.Env object at 0x7fb9be64a300>
2023-11-21 13:23:04,305 - rasterio.env - DEBUG - Starting outermost env
2023-11-21 13:23:04,305 - rasterio.env - DEBUG - No GDAL environment exists
2023-11-21 13:23:04,305 - rasterio.env - DEBUG - New GDAL environment <rasterio._env.GDALEnv object at 0x7fb9be64a3e0> created
2023-11-21 13:23:04,306 - rasterio._env - DEBUG - GDAL data found in package: path='/home/swx/miniconda3/envs/present_weather/lib/python3.12/site-packages/rasterio/gdal_data'.
2023-11-21 13:23:04,306 - rasterio._env - DEBUG - PROJ_LIB found in environment.
2023-11-21 13:23:04,306 - rasterio._env - DEBUG - Started GDALEnv: self=<rasterio._env.GDALEnv object at 0x7fb9be64a3e0>.
2023-11-21 13:23:04,306 - rasterio.env - DEBUG - Entered env context: <rasterio.env.Env object at 0x7fb9be64a300>
2023-11-21 13:23:04,307 - rasterio.env - DEBUG - Got a copy of environment <rasterio._env.GDALEnv object at 0x7fb9be64a3e0> options
2023-11-21 13:23:04,307 - rasterio.env - DEBUG - Entering env context: <rasterio.env.Env object at 0x7fb9be83de20>
2023-11-21 13:23:04,307 - rasterio.env - DEBUG - Got a copy of environment <rasterio._env.GDALEnv object at 0x7fb9be64a3e0> options
2023-11-21 13:23:04,307 - rasterio.env - DEBUG - Entered env context: <rasterio.env.Env object at 0x7fb9be83de20>
2023-11-21 13:23:04,307 - rasterio._base - DEBUG - Sharing flag: 0
2023-11-21 13:23:04,308 - rasterio._base - DEBUG - Nodata success: 1, Nodata value: nan
2023-11-21 13:23:04,308 - rasterio._base - DEBUG - Dataset <open DatasetReader name='https://radar.bmkg.go.id/raster/radarsatelit_202311211150.tif' mode='r'> is started.
2023-11-21 13:23:04,309 - rasterio.env - DEBUG - Exiting env context: <rasterio.env.Env object at 0x7fb9be83de20>
2023-11-21 13:23:04,309 - rasterio.env - DEBUG - Cleared existing <rasterio._env.GDALEnv object at 0x7fb9be64a3e0> options
2023-11-21 13:23:04,309 - rasterio._env - DEBUG - Stopped GDALEnv <rasterio._env.GDALEnv object at 0x7fb9be64a3e0>.
2023-11-21 13:23:04,309 - rasterio.env - DEBUG - No GDAL environment exists
2023-11-21 13:23:04,309 - rasterio.env - DEBUG - New GDAL environment <rasterio._env.GDALEnv object at 0x7fb9be64a3e0> created
2023-11-21 13:23:04,309 - rasterio._env - DEBUG - GDAL data found in package: path='/home/swx/miniconda3/envs/present_weather/lib/python3.12/site-packages/rasterio/gdal_data'.
2023-11-21 13:23:04,309 - rasterio._env - DEBUG - PROJ_LIB found in environment.
2023-11-21 13:23:04,310 - rasterio._env - DEBUG - Started GDALEnv: self=<rasterio._env.GDALEnv object at 0x7fb9be64a3e0>.
2023-11-21 13:23:04,310 - rasterio.env - DEBUG - Exited env context: <rasterio.env.Env object at 0x7fb9be83de20>
2023-11-21 13:23:04,337 - rasterio._io - DEBUG - Output nodata value read from file: nan
2023-11-21 13:23:04,338 - rasterio._io - DEBUG - Output nodata values: [nan]
2023-11-21 13:23:04,338 - rasterio._io - DEBUG - all_valid: False
2023-11-21 13:23:04,338 - rasterio._io - DEBUG - mask_flags: ([<MaskFlags.nodata: 8>],)
2023-11-21 13:23:04,339 - rasterio._io - DEBUG - Jump straight to _read()
2023-11-21 13:23:04,339 - rasterio._io - DEBUG - Window: Window(col_off=0, row_off=0, width=10215, height=3792)
2023-11-21 13:23:04,339 - rasterio._io - DEBUG - IO window xoff=0.0 yoff=0.0 width=10215.0 height=3792.0
2023-11-21 13:23:05,120 - rasterio.env - DEBUG - Exiting env context: <rasterio.env.Env object at 0x7fb9be64a300>
2023-11-21 13:23:05,121 - rasterio.env - DEBUG - Cleared existing <rasterio._env.GDALEnv object at 0x7fb9be64a3e0> options
2023-11-21 13:23:05,121 - rasterio._env - DEBUG - Stopped GDALEnv <rasterio._env.GDALEnv object at 0x7fb9be64a3e0>.
2023-11-21 13:23:05,121 - rasterio.env - DEBUG - Exiting outermost env
2023-11-21 13:23:05,121 - rasterio.env - DEBUG - Exited env context: <rasterio.env.Env object at 0x7fb9be64a300>
2023-11-21 13:23:05,123 - urllib3.connectionpool - DEBUG - Starting new HTTPS connection (1): radar.bmkg.go.id:8060
2023-11-21 13:23:10,204 - urllib3.connectionpool - DEBUG - https://radar.bmkg.go.id:8060 "GET /getLatestLD?typeData=1 HTTP/1.1" 200 62056
2023-11-21 13:23:10,234 - asyncio - DEBUG - Using selector: EpollSelector
2023-11-21 13:23:16,977 - root - INFO - dask.bag<lambda, npartitions=34>
2023-11-21 13:23:21,579 - root - INFO - Initiating present weather
2023-11-21 13:23:21,584 - urllib3.connectionpool - DEBUG - Starting new HTTPS connection (1): radar.bmkg.go.id:8060
2023-11-21 13:23:21,723 - urllib3.connectionpool - DEBUG - https://radar.bmkg.go.id:8060 "GET /getRadarGeotif?token=19387e71e78522ae4172ec0fda640983b8438c9cfa0ca571623cb69d8327&radar=amandemenForecast&type=latest HTTP/1.1" 200 90
2023-11-21 13:23:21,729 - rasterio.env - DEBUG - Entering env context: <rasterio.env.Env object at 0x7fade64e28d0>
2023-11-21 13:23:21,731 - rasterio.env - DEBUG - Starting outermost env
2023-11-21 13:23:21,731 - rasterio.env - DEBUG - No GDAL environment exists
2023-11-21 13:23:21,731 - rasterio.env - DEBUG - New GDAL environment <rasterio._env.GDALEnv object at 0x7fade692e620> created
2023-11-21 13:23:21,736 - rasterio._filepath - DEBUG - Installing FilePath filesystem handler plugin...
2023-11-21 13:23:21,736 - rasterio._env - DEBUG - GDAL_DATA found in environment.
2023-11-21 13:23:21,736 - rasterio._env - DEBUG - PROJ_DATA found in environment.
2023-11-21 13:23:21,737 - rasterio._env - DEBUG - Started GDALEnv: self=<rasterio._env.GDALEnv object at 0x7fade692e620>.
2023-11-21 13:23:21,737 - rasterio.env - DEBUG - Entered env context: <rasterio.env.Env object at 0x7fade64e28d0>
2023-11-21 13:23:21,737 - rasterio._base - DEBUG - Sharing flag: 0
2023-11-21 13:23:21,989 - rasterio._base - DEBUG - Nodata success: 1, Nodata value: nan
2023-11-21 13:23:21,990 - rasterio._base - DEBUG - Dataset <open DatasetReader name='https://radar.bmkg.go.id/raster/radarsatelit_202311211150.tif' mode='r'> is started.
2023-11-21 13:23:21,991 - rasterio.env - DEBUG - Exiting env context: <rasterio.env.Env object at 0x7fade64e28d0>
2023-11-21 13:23:21,991 - rasterio.env - DEBUG - Cleared existing <rasterio._env.GDALEnv object at 0x7fade692e620> options
2023-11-21 13:23:21,991 - rasterio._env - DEBUG - Stopped GDALEnv <rasterio._env.GDALEnv object at 0x7fade692e620>.
2023-11-21 13:23:21,992 - rasterio.env - DEBUG - Exiting outermost env
2023-11-21 13:23:21,992 - rasterio.env - DEBUG - Exited env context: <rasterio.env.Env object at 0x7fade64e28d0>
2023-11-21 13:23:21,992 - rasterio.env - DEBUG - Entering env context: <rasterio.env.Env object at 0x7fadffbe3f20>
2023-11-21 13:23:21,992 - rasterio.env - DEBUG - Starting outermost env
2023-11-21 13:23:21,992 - rasterio.env - DEBUG - No GDAL environment exists
2023-11-21 13:23:21,992 - rasterio.env - DEBUG - New GDAL environment <rasterio._env.GDALEnv object at 0x7fade626f400> created
2023-11-21 13:23:21,993 - rasterio._env - DEBUG - GDAL_DATA found in environment.
2023-11-21 13:23:21,993 - rasterio._env - DEBUG - PROJ_DATA found in environment.
2023-11-21 13:23:21,994 - rasterio._env - DEBUG - Started GDALEnv: self=<rasterio._env.GDALEnv object at 0x7fade626f400>.
2023-11-21 13:23:21,994 - rasterio.env - DEBUG - Entered env context: <rasterio.env.Env object at 0x7fadffbe3f20>
2023-11-21 13:23:21,994 - rasterio.env - DEBUG - Got a copy of environment <rasterio._env.GDALEnv object at 0x7fade626f400> options
2023-11-21 13:23:21,995 - rasterio.env - DEBUG - Entering env context: <rasterio.env.Env object at 0x7fadffb96990>
2023-11-21 13:23:21,995 - rasterio.env - DEBUG - Got a copy of environment <rasterio._env.GDALEnv object at 0x7fade626f400> options
2023-11-21 13:23:21,995 - rasterio.env - DEBUG - Entered env context: <rasterio.env.Env object at 0x7fadffb96990>
2023-11-21 13:23:21,996 - rasterio._base - DEBUG - Sharing flag: 0
2023-11-21 13:23:21,998 - rasterio._base - DEBUG - Nodata success: 1, Nodata value: nan
2023-11-21 13:23:21,999 - rasterio._base - DEBUG - Dataset <open DatasetReader name='https://radar.bmkg.go.id/raster/radarsatelit_202311211150.tif' mode='r'> is started.
2023-11-21 13:23:21,999 - rasterio.env - DEBUG - Exiting env context: <rasterio.env.Env object at 0x7fadffb96990>
2023-11-21 13:23:21,999 - rasterio.env - DEBUG - Cleared existing <rasterio._env.GDALEnv object at 0x7fade626f400> options
2023-11-21 13:23:21,999 - rasterio._env - DEBUG - Stopped GDALEnv <rasterio._env.GDALEnv object at 0x7fade626f400>.
2023-11-21 13:23:22,000 - rasterio.env - DEBUG - No GDAL environment exists
2023-11-21 13:23:22,000 - rasterio.env - DEBUG - New GDAL environment <rasterio._env.GDALEnv object at 0x7fade626f400> created
2023-11-21 13:23:22,000 - rasterio._env - DEBUG - GDAL_DATA found in environment.
2023-11-21 13:23:22,001 - rasterio._env - DEBUG - PROJ_DATA found in environment.
2023-11-21 13:23:22,001 - rasterio._env - DEBUG - Started GDALEnv: self=<rasterio._env.GDALEnv object at 0x7fade626f400>.
2023-11-21 13:23:22,001 - rasterio.env - DEBUG - Exited env context: <rasterio.env.Env object at 0x7fadffb96990>
2023-11-21 13:23:22,044 - rasterio._io - DEBUG - Output nodata value read from file: nan
2023-11-21 13:23:22,044 - rasterio._io - DEBUG - Output nodata values: [nan]
2023-11-21 13:23:22,045 - rasterio._io - DEBUG - all_valid: False
2023-11-21 13:23:22,045 - rasterio._io - DEBUG - mask_flags: ([<MaskFlags.nodata: 8>],)
2023-11-21 13:23:22,046 - rasterio._io - DEBUG - Jump straight to _read()
2023-11-21 13:23:22,046 - rasterio._io - DEBUG - Window: Window(col_off=0, row_off=0, width=10215, height=3792)
2023-11-21 13:23:22,047 - rasterio._io - DEBUG - IO window xoff=0.0 yoff=0.0 width=10215.0 height=3792.0
2023-11-21 13:23:23,940 - rasterio.env - DEBUG - Exiting env context: <rasterio.env.Env object at 0x7fadffbe3f20>
2023-11-21 13:23:23,941 - rasterio.env - DEBUG - Cleared existing <rasterio._env.GDALEnv object at 0x7fade626f400> options
2023-11-21 13:23:23,941 - rasterio._env - DEBUG - Stopped GDALEnv <rasterio._env.GDALEnv object at 0x7fade626f400>.
2023-11-21 13:23:23,941 - rasterio.env - DEBUG - Exiting outermost env
2023-11-21 13:23:23,941 - rasterio.env - DEBUG - Exited env context: <rasterio.env.Env object at 0x7fadffbe3f20>
2023-11-21 13:23:23,945 - urllib3.connectionpool - DEBUG - Starting new HTTPS connection (1): radar.bmkg.go.id:8060
2023-11-21 13:23:24,033 - urllib3.connectionpool - DEBUG - https://radar.bmkg.go.id:8060 "GET /getLatestLD?typeData=1 HTTP/1.1" 200 62056
2023-11-21 13:23:24,081 - asyncio - DEBUG - Using selector: EpollSelector
2023-11-21 13:23:43,190 - root - INFO - dask.bag<lambda, npartitions=34>
2023-11-21 13:33:07,404 - mylogger - ERROR - Exception: 
NoneType: None
2023-11-21 13:33:07,448 - asyncio - ERROR - Task exception was never retrieved
future: <Task finished name='Task-2230' coro=<Client._gather.<locals>.wait() done, defined at /home/swx/miniconda3/envs/present_weather/lib/python3.12/site-packages/distributed/client.py:2209> exception=AllExit()>
Traceback (most recent call last):
  File "/home/swx/miniconda3/envs/present_weather/lib/python3.12/site-packages/distributed/client.py", line 2218, in wait
    raise AllExit()
distributed.client.AllExit
2023-11-21 13:33:07,450 - asyncio - ERROR - Task exception was never retrieved
future: <Task finished name='Task-2229' coro=<Client._gather.<locals>.wait() done, defined at /home/swx/miniconda3/envs/present_weather/lib/python3.12/site-packages/distributed/client.py:2209> exception=AllExit()>
Traceback (most recent call last):
  File "/home/swx/miniconda3/envs/present_weather/lib/python3.12/site-packages/distributed/client.py", line 2218, in wait
    raise AllExit()
distributed.client.AllExit
2023-11-21 13:33:07,451 - asyncio - ERROR - Task exception was never retrieved
future: <Task finished name='Task-2228' coro=<Client._gather.<locals>.wait() done, defined at /home/swx/miniconda3/envs/present_weather/lib/python3.12/site-packages/distributed/client.py:2209> exception=AllExit()>
Traceback (most recent call last):
  File "/home/swx/miniconda3/envs/present_weather/lib/python3.12/site-packages/distributed/client.py", line 2218, in wait
    raise AllExit()
distributed.client.AllExit
2023-11-21 13:33:07,452 - asyncio - ERROR - Task exception was never retrieved
future: <Task finished name='Task-2227' coro=<Client._gather.<locals>.wait() done, defined at /home/swx/miniconda3/envs/present_weather/lib/python3.12/site-packages/distributed/client.py:2209> exception=AllExit()>
Traceback (most recent call last):
  File "/home/swx/miniconda3/envs/present_weather/lib/python3.12/site-packages/distributed/client.py", line 2218, in wait
    raise AllExit()
distributed.client.AllExit
2023-11-21 13:33:07,453 - asyncio - ERROR - Task exception was never retrieved
future: <Task finished name='Task-2226' coro=<Client._gather.<locals>.wait() done, defined at /home/swx/miniconda3/envs/present_weather/lib/python3.12/site-packages/distributed/client.py:2209> exception=AllExit()>
Traceback (most recent call last):
  File "/home/swx/miniconda3/envs/present_weather/lib/python3.12/site-packages/distributed/client.py", line 2218, in wait
    raise AllExit()
distributed.client.AllExit
2023-11-21 13:33:07,455 - asyncio - ERROR - Task exception was never retrieved
future: <Task finished name='Task-2224' coro=<Client._gather.<locals>.wait() done, defined at /home/swx/miniconda3/envs/present_weather/lib/python3.12/site-packages/distributed/client.py:2209> exception=AllExit()>
Traceback (most recent call last):
  File "/home/swx/miniconda3/envs/present_weather/lib/python3.12/site-packages/distributed/client.py", line 2218, in wait
    raise AllExit()
distributed.client.AllExit
2023-11-21 13:33:07,457 - asyncio - ERROR - Task exception was never retrieved
future: <Task finished name='Task-2223' coro=<Client._gather.<locals>.wait() done, defined at /home/swx/miniconda3/envs/present_weather/lib/python3.12/site-packages/distributed/client.py:2209> exception=AllExit()>
Traceback (most recent call last):
  File "/home/swx/miniconda3/envs/present_weather/lib/python3.12/site-packages/distributed/client.py", line 2218, in wait
    raise AllExit()
distributed.client.AllExit
2023-11-21 13:33:07,458 - asyncio - ERROR - Task exception was never retrieved
future: <Task finished name='Task-2222' coro=<Client._gather.<locals>.wait() done, defined at /home/swx/miniconda3/envs/present_weather/lib/python3.12/site-packages/distributed/client.py:2209> exception=AllExit()>
Traceback (most recent call last):
  File "/home/swx/miniconda3/envs/present_weather/lib/python3.12/site-packages/distributed/client.py", line 2218, in wait
    raise AllExit()
distributed.client.AllExit
2023-11-21 13:33:07,459 - asyncio - ERROR - Task exception was never retrieved
future: <Task finished name='Task-2221' coro=<Client._gather.<locals>.wait() done, defined at /home/swx/miniconda3/envs/present_weather/lib/python3.12/site-packages/distributed/client.py:2209> exception=AllExit()>
Traceback (most recent call last):
  File "/home/swx/miniconda3/envs/present_weather/lib/python3.12/site-packages/distributed/client.py", line 2218, in wait
    raise AllExit()
distributed.client.AllExit
2023-11-21 13:33:07,460 - asyncio - ERROR - Task exception was never retrieved
future: <Task finished name='Task-2220' coro=<Client._gather.<locals>.wait() done, defined at /home/swx/miniconda3/envs/present_weather/lib/python3.12/site-packages/distributed/client.py:2209> exception=AllExit()>
Traceback (most recent call last):
  File "/home/swx/miniconda3/envs/present_weather/lib/python3.12/site-packages/distributed/client.py", line 2218, in wait
    raise AllExit()
distributed.client.AllExit
2023-11-21 13:33:07,461 - asyncio - ERROR - Task exception was never retrieved
future: <Task finished name='Task-2219' coro=<Client._gather.<locals>.wait() done, defined at /home/swx/miniconda3/envs/present_weather/lib/python3.12/site-packages/distributed/client.py:2209> exception=AllExit()>
Traceback (most recent call last):
  File "/home/swx/miniconda3/envs/present_weather/lib/python3.12/site-packages/distributed/client.py", line 2218, in wait
    raise AllExit()
distributed.client.AllExit
2023-11-21 13:33:07,461 - asyncio - ERROR - Task exception was never retrieved
future: <Task finished name='Task-2218' coro=<Client._gather.<locals>.wait() done, defined at /home/swx/miniconda3/envs/present_weather/lib/python3.12/site-packages/distributed/client.py:2209> exception=AllExit()>
Traceback (most recent call last):
  File "/home/swx/miniconda3/envs/present_weather/lib/python3.12/site-packages/distributed/client.py", line 2218, in wait
    raise AllExit()
distributed.client.AllExit
2023-11-21 13:33:07,464 - asyncio - ERROR - Task exception was never retrieved
future: <Task finished name='Task-2216' coro=<Client._gather.<locals>.wait() done, defined at /home/swx/miniconda3/envs/present_weather/lib/python3.12/site-packages/distributed/client.py:2209> exception=AllExit()>
Traceback (most recent call last):
  File "/home/swx/miniconda3/envs/present_weather/lib/python3.12/site-packages/distributed/client.py", line 2218, in wait
    raise AllExit()
distributed.client.AllExit
2023-11-21 13:33:07,466 - asyncio - ERROR - Task exception was never retrieved
future: <Task finished name='Task-2214' coro=<Client._gather.<locals>.wait() done, defined at /home/swx/miniconda3/envs/present_weather/lib/python3.12/site-packages/distributed/client.py:2209> exception=AllExit()>
Traceback (most recent call last):
  File "/home/swx/miniconda3/envs/present_weather/lib/python3.12/site-packages/distributed/client.py", line 2218, in wait
    raise AllExit()
distributed.client.AllExit
2023-11-21 13:33:07,468 - asyncio - ERROR - Task exception was never retrieved
future: <Task finished name='Task-2210' coro=<Client._gather.<locals>.wait() done, defined at /home/swx/miniconda3/envs/present_weather/lib/python3.12/site-packages/distributed/client.py:2209> exception=AllExit()>
Traceback (most recent call last):
  File "/home/swx/miniconda3/envs/present_weather/lib/python3.12/site-packages/distributed/client.py", line 2218, in wait
    raise AllExit()
distributed.client.AllExit
2023-11-21 13:33:07,470 - asyncio - ERROR - Task exception was never retrieved
future: <Task finished name='Task-2208' coro=<Client._gather.<locals>.wait() done, defined at /home/swx/miniconda3/envs/present_weather/lib/python3.12/site-packages/distributed/client.py:2209> exception=AllExit()>
Traceback (most recent call last):
  File "/home/swx/miniconda3/envs/present_weather/lib/python3.12/site-packages/distributed/client.py", line 2218, in wait
    raise AllExit()
distributed.client.AllExit
2023-11-21 13:33:07,471 - asyncio - ERROR - Task exception was never retrieved
future: <Task finished name='Task-2240' coro=<Client._gather.<locals>.wait() done, defined at /home/swx/miniconda3/envs/present_weather/lib/python3.12/site-packages/distributed/client.py:2209> exception=AllExit()>
Traceback (most recent call last):
  File "/home/swx/miniconda3/envs/present_weather/lib/python3.12/site-packages/distributed/client.py", line 2218, in wait
    raise AllExit()
distributed.client.AllExit
2023-11-21 13:33:07,472 - asyncio - ERROR - Task exception was never retrieved
future: <Task finished name='Task-2239' coro=<Client._gather.<locals>.wait() done, defined at /home/swx/miniconda3/envs/present_weather/lib/python3.12/site-packages/distributed/client.py:2209> exception=AllExit()>
Traceback (most recent call last):
  File "/home/swx/miniconda3/envs/present_weather/lib/python3.12/site-packages/distributed/client.py", line 2218, in wait
    raise AllExit()
distributed.client.AllExit
2023-11-21 13:33:07,473 - asyncio - ERROR - Task exception was never retrieved
future: <Task finished name='Task-2215' coro=<Client._gather.<locals>.wait() done, defined at /home/swx/miniconda3/envs/present_weather/lib/python3.12/site-packages/distributed/client.py:2209> exception=AllExit()>
Traceback (most recent call last):
  File "/home/swx/miniconda3/envs/present_weather/lib/python3.12/site-packages/distributed/client.py", line 2218, in wait
    raise AllExit()
distributed.client.AllExit
2023-11-21 13:33:07,473 - asyncio - ERROR - Task exception was never retrieved
future: <Task finished name='Task-2236' coro=<Client._gather.<locals>.wait() done, defined at /home/swx/miniconda3/envs/present_weather/lib/python3.12/site-packages/distributed/client.py:2209> exception=AllExit()>
Traceback (most recent call last):
  File "/home/swx/miniconda3/envs/present_weather/lib/python3.12/site-packages/distributed/client.py", line 2218, in wait
    raise AllExit()
distributed.client.AllExit
2023-11-21 13:33:07,474 - asyncio - ERROR - Task exception was never retrieved
future: <Task finished name='Task-2235' coro=<Client._gather.<locals>.wait() done, defined at /home/swx/miniconda3/envs/present_weather/lib/python3.12/site-packages/distributed/client.py:2209> exception=AllExit()>
Traceback (most recent call last):
  File "/home/swx/miniconda3/envs/present_weather/lib/python3.12/site-packages/distributed/client.py", line 2218, in wait
    raise AllExit()
distributed.client.AllExit
2023-11-21 13:33:07,486 - asyncio - ERROR - Task exception was never retrieved
future: <Task finished name='Task-2234' coro=<Client._gather.<locals>.wait() done, defined at /home/swx/miniconda3/envs/present_weather/lib/python3.12/site-packages/distributed/client.py:2209> exception=AllExit()>
Traceback (most recent call last):
  File "/home/swx/miniconda3/envs/present_weather/lib/python3.12/site-packages/distributed/client.py", line 2218, in wait
    raise AllExit()
distributed.client.AllExit
2023-11-21 13:33:07,487 - asyncio - ERROR - Task exception was never retrieved
future: <Task finished name='Task-2233' coro=<Client._gather.<locals>.wait() done, defined at /home/swx/miniconda3/envs/present_weather/lib/python3.12/site-packages/distributed/client.py:2209> exception=AllExit()>
Traceback (most recent call last):
  File "/home/swx/miniconda3/envs/present_weather/lib/python3.12/site-packages/distributed/client.py", line 2218, in wait
    raise AllExit()
distributed.client.AllExit
2023-11-21 13:33:07,488 - asyncio - ERROR - Task exception was never retrieved
future: <Task finished name='Task-2207' coro=<Client._gather.<locals>.wait() done, defined at /home/swx/miniconda3/envs/present_weather/lib/python3.12/site-packages/distributed/client.py:2209> exception=AllExit()>
Traceback (most recent call last):
  File "/home/swx/miniconda3/envs/present_weather/lib/python3.12/site-packages/distributed/client.py", line 2218, in wait
    raise AllExit()
distributed.client.AllExit
2023-11-21 13:33:07,489 - asyncio - ERROR - Task exception was never retrieved
future: <Task finished name='Task-2209' coro=<Client._gather.<locals>.wait() done, defined at /home/swx/miniconda3/envs/present_weather/lib/python3.12/site-packages/distributed/client.py:2209> exception=AllExit()>
Traceback (most recent call last):
  File "/home/swx/miniconda3/envs/present_weather/lib/python3.12/site-packages/distributed/client.py", line 2218, in wait
    raise AllExit()
distributed.client.AllExit
2023-11-21 13:33:07,490 - asyncio - ERROR - Task exception was never retrieved
future: <Task finished name='Task-2212' coro=<Client._gather.<locals>.wait() done, defined at /home/swx/miniconda3/envs/present_weather/lib/python3.12/site-packages/distributed/client.py:2209> exception=AllExit()>
Traceback (most recent call last):
  File "/home/swx/miniconda3/envs/present_weather/lib/python3.12/site-packages/distributed/client.py", line 2218, in wait
    raise AllExit()
distributed.client.AllExit
2023-11-21 13:33:07,491 - asyncio - ERROR - Task exception was never retrieved
future: <Task finished name='Task-2217' coro=<Client._gather.<locals>.wait() done, defined at /home/swx/miniconda3/envs/present_weather/lib/python3.12/site-packages/distributed/client.py:2209> exception=AllExit()>
Traceback (most recent call last):
  File "/home/swx/miniconda3/envs/present_weather/lib/python3.12/site-packages/distributed/client.py", line 2218, in wait
    raise AllExit()
distributed.client.AllExit
2023-11-21 13:33:07,492 - asyncio - ERROR - Task exception was never retrieved
future: <Task finished name='Task-2238' coro=<Client._gather.<locals>.wait() done, defined at /home/swx/miniconda3/envs/present_weather/lib/python3.12/site-packages/distributed/client.py:2209> exception=AllExit()>
Traceback (most recent call last):
  File "/home/swx/miniconda3/envs/present_weather/lib/python3.12/site-packages/distributed/client.py", line 2218, in wait
    raise AllExit()
distributed.client.AllExit
2023-11-21 13:33:07,493 - asyncio - ERROR - Task exception was never retrieved
future: <Task finished name='Task-2237' coro=<Client._gather.<locals>.wait() done, defined at /home/swx/miniconda3/envs/present_weather/lib/python3.12/site-packages/distributed/client.py:2209> exception=AllExit()>
Traceback (most recent call last):
  File "/home/swx/miniconda3/envs/present_weather/lib/python3.12/site-packages/distributed/client.py", line 2218, in wait
    raise AllExit()
distributed.client.AllExit
2023-11-21 13:48:55,068 - root - INFO - Total elapsed time: 0:25:51.045701
