2023-11-22 08:03:03,399 - root - INFO - Initiating present weather
2023-11-22 08:03:03,404 - urllib3.connectionpool - DEBUG - Starting new HTTPS connection (1): radar.bmkg.go.id:8060
2023-11-22 08:03:03,473 - urllib3.connectionpool - DEBUG - https://radar.bmkg.go.id:8060 "GET /getRadarGeotif?token=19387e71e78522ae4172ec0fda640983b8438c9cfa0ca571623cb69d8327&radar=amandemenForecast&type=latest HTTP/1.1" 200 90
2023-11-22 08:03:03,476 - rasterio.env - DEBUG - Entering env context: <rasterio.env.Env object at 0x7f32c0db6720>
2023-11-22 08:03:03,477 - rasterio.env - DEBUG - Starting outermost env
2023-11-22 08:03:03,477 - rasterio.env - DEBUG - No GDAL environment exists
2023-11-22 08:03:03,477 - rasterio.env - DEBUG - New GDAL environment <rasterio._env.GDALEnv object at 0x7f32c0e80d30> created
2023-11-22 08:03:03,482 - rasterio._filepath - DEBUG - Installing FilePath filesystem handler plugin...
2023-11-22 08:03:03,482 - rasterio._env - DEBUG - GDAL data found in package: path='/home/swx/miniconda3/envs/present_weather/lib/python3.12/site-packages/rasterio/gdal_data'.
2023-11-22 08:03:03,482 - rasterio._env - DEBUG - PROJ_LIB found in environment.
2023-11-22 08:03:03,483 - rasterio._env - DEBUG - Started GDALEnv: self=<rasterio._env.GDALEnv object at 0x7f32c0e80d30>.
2023-11-22 08:03:03,483 - rasterio.env - DEBUG - Entered env context: <rasterio.env.Env object at 0x7f32c0db6720>
2023-11-22 08:03:03,483 - rasterio._base - DEBUG - Sharing flag: 0
2023-11-22 08:03:03,669 - rasterio._base - DEBUG - Nodata success: 1, Nodata value: nan
2023-11-22 08:03:03,669 - rasterio._base - DEBUG - Dataset <open DatasetReader name='https://radar.bmkg.go.id/raster/radarsatelit_202311220800.tif' mode='r'> is started.
2023-11-22 08:03:03,669 - rasterio.env - DEBUG - Exiting env context: <rasterio.env.Env object at 0x7f32c0db6720>
2023-11-22 08:03:03,669 - rasterio.env - DEBUG - Cleared existing <rasterio._env.GDALEnv object at 0x7f32c0e80d30> options
2023-11-22 08:03:03,669 - rasterio._env - DEBUG - Stopped GDALEnv <rasterio._env.GDALEnv object at 0x7f32c0e80d30>.
2023-11-22 08:03:03,670 - rasterio.env - DEBUG - Exiting outermost env
2023-11-22 08:03:03,670 - rasterio.env - DEBUG - Exited env context: <rasterio.env.Env object at 0x7f32c0db6720>
2023-11-22 08:03:03,670 - rasterio.env - DEBUG - Entering env context: <rasterio.env.Env object at 0x7f32c104d760>
2023-11-22 08:03:03,670 - rasterio.env - DEBUG - Starting outermost env
2023-11-22 08:03:03,670 - rasterio.env - DEBUG - No GDAL environment exists
2023-11-22 08:03:03,670 - rasterio.env - DEBUG - New GDAL environment <rasterio._env.GDALEnv object at 0x7f32c0e80d30> created
2023-11-22 08:03:03,671 - rasterio._env - DEBUG - GDAL data found in package: path='/home/swx/miniconda3/envs/present_weather/lib/python3.12/site-packages/rasterio/gdal_data'.
2023-11-22 08:03:03,671 - rasterio._env - DEBUG - PROJ_LIB found in environment.
2023-11-22 08:03:03,671 - rasterio._env - DEBUG - Started GDALEnv: self=<rasterio._env.GDALEnv object at 0x7f32c0e80d30>.
2023-11-22 08:03:03,671 - rasterio.env - DEBUG - Entered env context: <rasterio.env.Env object at 0x7f32c104d760>
2023-11-22 08:03:03,671 - rasterio.env - DEBUG - Got a copy of environment <rasterio._env.GDALEnv object at 0x7f32c0e80d30> options
2023-11-22 08:03:03,672 - rasterio.env - DEBUG - Entering env context: <rasterio.env.Env object at 0x7f330217cbf0>
2023-11-22 08:03:03,672 - rasterio.env - DEBUG - Got a copy of environment <rasterio._env.GDALEnv object at 0x7f32c0e80d30> options
2023-11-22 08:03:03,672 - rasterio.env - DEBUG - Entered env context: <rasterio.env.Env object at 0x7f330217cbf0>
2023-11-22 08:03:03,672 - rasterio._base - DEBUG - Sharing flag: 0
2023-11-22 08:03:03,673 - rasterio._base - DEBUG - Nodata success: 1, Nodata value: nan
2023-11-22 08:03:03,673 - rasterio._base - DEBUG - Dataset <open DatasetReader name='https://radar.bmkg.go.id/raster/radarsatelit_202311220800.tif' mode='r'> is started.
2023-11-22 08:03:03,673 - rasterio.env - DEBUG - Exiting env context: <rasterio.env.Env object at 0x7f330217cbf0>
2023-11-22 08:03:03,673 - rasterio.env - DEBUG - Cleared existing <rasterio._env.GDALEnv object at 0x7f32c0e80d30> options
2023-11-22 08:03:03,673 - rasterio._env - DEBUG - Stopped GDALEnv <rasterio._env.GDALEnv object at 0x7f32c0e80d30>.
2023-11-22 08:03:03,673 - rasterio.env - DEBUG - No GDAL environment exists
2023-11-22 08:03:03,673 - rasterio.env - DEBUG - New GDAL environment <rasterio._env.GDALEnv object at 0x7f32c0e80d30> created
2023-11-22 08:03:03,674 - rasterio._env - DEBUG - GDAL data found in package: path='/home/swx/miniconda3/envs/present_weather/lib/python3.12/site-packages/rasterio/gdal_data'.
2023-11-22 08:03:03,674 - rasterio._env - DEBUG - PROJ_LIB found in environment.
2023-11-22 08:03:03,674 - rasterio._env - DEBUG - Started GDALEnv: self=<rasterio._env.GDALEnv object at 0x7f32c0e80d30>.
2023-11-22 08:03:03,674 - rasterio.env - DEBUG - Exited env context: <rasterio.env.Env object at 0x7f330217cbf0>
2023-11-22 08:03:03,701 - rasterio._io - DEBUG - Output nodata value read from file: nan
2023-11-22 08:03:03,701 - rasterio._io - DEBUG - Output nodata values: [nan]
2023-11-22 08:03:03,701 - rasterio._io - DEBUG - all_valid: False
2023-11-22 08:03:03,701 - rasterio._io - DEBUG - mask_flags: ([<MaskFlags.nodata: 8>],)
2023-11-22 08:03:03,702 - rasterio._io - DEBUG - Jump straight to _read()
2023-11-22 08:03:03,702 - rasterio._io - DEBUG - Window: Window(col_off=0, row_off=0, width=10215, height=3792)
2023-11-22 08:03:03,702 - rasterio._io - DEBUG - IO window xoff=0.0 yoff=0.0 width=10215.0 height=3792.0
2023-11-22 08:03:04,458 - rasterio.env - DEBUG - Exiting env context: <rasterio.env.Env object at 0x7f32c104d760>
2023-11-22 08:03:04,458 - rasterio.env - DEBUG - Cleared existing <rasterio._env.GDALEnv object at 0x7f32c0e80d30> options
2023-11-22 08:03:04,458 - rasterio._env - DEBUG - Stopped GDALEnv <rasterio._env.GDALEnv object at 0x7f32c0e80d30>.
2023-11-22 08:03:04,458 - rasterio.env - DEBUG - Exiting outermost env
2023-11-22 08:03:04,458 - rasterio.env - DEBUG - Exited env context: <rasterio.env.Env object at 0x7f32c104d760>
2023-11-22 08:03:04,460 - urllib3.connectionpool - DEBUG - Starting new HTTPS connection (1): radar.bmkg.go.id:8060
2023-11-22 08:03:04,531 - urllib3.connectionpool - DEBUG - https://radar.bmkg.go.id:8060 "GET /getLatestLD?typeData=1 HTTP/1.1" 200 104778
2023-11-22 08:03:04,568 - asyncio - DEBUG - Using selector: EpollSelector
2023-11-22 08:03:11,382 - root - INFO - dask.bag<lambda, npartitions=34>
2023-11-22 08:03:19,680 - root - INFO - Initiating present weather
2023-11-22 08:03:19,681 - asyncio - DEBUG - Using selector: EpollSelector
2023-11-22 08:03:27,945 - urllib3.connectionpool - DEBUG - Starting new HTTPS connection (1): radar.bmkg.go.id:8060
2023-11-22 08:03:28,062 - urllib3.connectionpool - DEBUG - https://radar.bmkg.go.id:8060 "GET /getRadarGeotif?token=19387e71e78522ae4172ec0fda640983b8438c9cfa0ca571623cb69d8327&radar=amandemenForecast&type=latest HTTP/1.1" 200 90
2023-11-22 08:03:28,067 - rasterio.env - DEBUG - Entering env context: <rasterio.env.Env object at 0x7f9e842e0650>
2023-11-22 08:03:28,069 - rasterio.env - DEBUG - Starting outermost env
2023-11-22 08:03:28,070 - rasterio.env - DEBUG - No GDAL environment exists
2023-11-22 08:03:28,070 - rasterio.env - DEBUG - New GDAL environment <rasterio._env.GDALEnv object at 0x7f9e7de19720> created
2023-11-22 08:03:28,075 - rasterio._filepath - DEBUG - Installing FilePath filesystem handler plugin...
2023-11-22 08:03:28,076 - rasterio._env - DEBUG - GDAL data found in package: path='/home/swx/miniconda3/envs/present_weather/lib/python3.12/site-packages/rasterio/gdal_data'.
2023-11-22 08:03:28,077 - rasterio._env - DEBUG - PROJ_LIB found in environment.
2023-11-22 08:03:28,077 - rasterio._env - DEBUG - Started GDALEnv: self=<rasterio._env.GDALEnv object at 0x7f9e7de19720>.
2023-11-22 08:03:28,077 - rasterio.env - DEBUG - Entered env context: <rasterio.env.Env object at 0x7f9e842e0650>
2023-11-22 08:03:28,078 - rasterio._base - DEBUG - Sharing flag: 0
2023-11-22 08:03:28,316 - rasterio._base - DEBUG - Nodata success: 1, Nodata value: nan
2023-11-22 08:03:28,318 - rasterio._base - DEBUG - Dataset <open DatasetReader name='https://radar.bmkg.go.id/raster/radarsatelit_202311220800.tif' mode='r'> is started.
2023-11-22 08:03:28,320 - rasterio.env - DEBUG - Exiting env context: <rasterio.env.Env object at 0x7f9e842e0650>
2023-11-22 08:03:28,321 - rasterio.env - DEBUG - Cleared existing <rasterio._env.GDALEnv object at 0x7f9e7de19720> options
2023-11-22 08:03:28,321 - rasterio._env - DEBUG - Stopped GDALEnv <rasterio._env.GDALEnv object at 0x7f9e7de19720>.
2023-11-22 08:03:28,321 - rasterio.env - DEBUG - Exiting outermost env
2023-11-22 08:03:28,321 - rasterio.env - DEBUG - Exited env context: <rasterio.env.Env object at 0x7f9e842e0650>
2023-11-22 08:03:28,321 - rasterio.env - DEBUG - Entering env context: <rasterio.env.Env object at 0x7f9e7de19730>
2023-11-22 08:03:28,321 - rasterio.env - DEBUG - Starting outermost env
2023-11-22 08:03:28,322 - rasterio.env - DEBUG - No GDAL environment exists
2023-11-22 08:03:28,322 - rasterio.env - DEBUG - New GDAL environment <rasterio._env.GDALEnv object at 0x7f9e7dd799f0> created
2023-11-22 08:03:28,323 - rasterio._env - DEBUG - GDAL data found in package: path='/home/swx/miniconda3/envs/present_weather/lib/python3.12/site-packages/rasterio/gdal_data'.
2023-11-22 08:03:28,323 - rasterio._env - DEBUG - PROJ_LIB found in environment.
2023-11-22 08:03:28,323 - rasterio._env - DEBUG - Started GDALEnv: self=<rasterio._env.GDALEnv object at 0x7f9e7dd799f0>.
2023-11-22 08:03:28,324 - rasterio.env - DEBUG - Entered env context: <rasterio.env.Env object at 0x7f9e7de19730>
2023-11-22 08:03:28,324 - rasterio.env - DEBUG - Got a copy of environment <rasterio._env.GDALEnv object at 0x7f9e7dd799f0> options
2023-11-22 08:03:28,325 - rasterio.env - DEBUG - Entering env context: <rasterio.env.Env object at 0x7f9e7db0d4f0>
2023-11-22 08:03:28,325 - rasterio.env - DEBUG - Got a copy of environment <rasterio._env.GDALEnv object at 0x7f9e7dd799f0> options
2023-11-22 08:03:28,325 - rasterio.env - DEBUG - Entered env context: <rasterio.env.Env object at 0x7f9e7db0d4f0>
2023-11-22 08:03:28,325 - rasterio._base - DEBUG - Sharing flag: 0
2023-11-22 08:03:28,327 - rasterio._base - DEBUG - Nodata success: 1, Nodata value: nan
2023-11-22 08:03:28,328 - rasterio._base - DEBUG - Dataset <open DatasetReader name='https://radar.bmkg.go.id/raster/radarsatelit_202311220800.tif' mode='r'> is started.
2023-11-22 08:03:28,328 - rasterio.env - DEBUG - Exiting env context: <rasterio.env.Env object at 0x7f9e7db0d4f0>
2023-11-22 08:03:28,328 - rasterio.env - DEBUG - Cleared existing <rasterio._env.GDALEnv object at 0x7f9e7dd799f0> options
2023-11-22 08:03:28,328 - rasterio._env - DEBUG - Stopped GDALEnv <rasterio._env.GDALEnv object at 0x7f9e7dd799f0>.
2023-11-22 08:03:28,328 - rasterio.env - DEBUG - No GDAL environment exists
2023-11-22 08:03:28,328 - rasterio.env - DEBUG - New GDAL environment <rasterio._env.GDALEnv object at 0x7f9e7dd799f0> created
2023-11-22 08:03:28,329 - rasterio._env - DEBUG - GDAL data found in package: path='/home/swx/miniconda3/envs/present_weather/lib/python3.12/site-packages/rasterio/gdal_data'.
2023-11-22 08:03:28,330 - rasterio._env - DEBUG - PROJ_LIB found in environment.
2023-11-22 08:03:28,330 - rasterio._env - DEBUG - Started GDALEnv: self=<rasterio._env.GDALEnv object at 0x7f9e7dd799f0>.
2023-11-22 08:03:28,331 - rasterio.env - DEBUG - Exited env context: <rasterio.env.Env object at 0x7f9e7db0d4f0>
2023-11-22 08:03:28,415 - rasterio._io - DEBUG - Output nodata value read from file: nan
2023-11-22 08:03:28,416 - rasterio._io - DEBUG - Output nodata values: [nan]
2023-11-22 08:03:28,417 - rasterio._io - DEBUG - all_valid: False
2023-11-22 08:03:28,418 - rasterio._io - DEBUG - mask_flags: ([<MaskFlags.nodata: 8>],)
2023-11-22 08:03:28,418 - rasterio._io - DEBUG - Jump straight to _read()
2023-11-22 08:03:28,418 - rasterio._io - DEBUG - Window: Window(col_off=0, row_off=0, width=10215, height=3792)
2023-11-22 08:03:28,419 - rasterio._io - DEBUG - IO window xoff=0.0 yoff=0.0 width=10215.0 height=3792.0
2023-11-22 08:03:30,307 - rasterio.env - DEBUG - Exiting env context: <rasterio.env.Env object at 0x7f9e7de19730>
2023-11-22 08:03:30,311 - rasterio.env - DEBUG - Cleared existing <rasterio._env.GDALEnv object at 0x7f9e7dd799f0> options
2023-11-22 08:03:30,312 - rasterio._env - DEBUG - Stopped GDALEnv <rasterio._env.GDALEnv object at 0x7f9e7dd799f0>.
2023-11-22 08:03:30,313 - rasterio.env - DEBUG - Exiting outermost env
2023-11-22 08:03:30,313 - rasterio.env - DEBUG - Exited env context: <rasterio.env.Env object at 0x7f9e7de19730>
2023-11-22 08:03:30,318 - urllib3.connectionpool - DEBUG - Starting new HTTPS connection (1): radar.bmkg.go.id:8060
2023-11-22 08:03:30,420 - urllib3.connectionpool - DEBUG - https://radar.bmkg.go.id:8060 "GET /getLatestLD?typeData=1 HTTP/1.1" 200 104778
2023-11-22 08:03:37,552 - root - INFO - dask.bag<lambda, npartitions=34>
2023-11-22 08:07:30,615 - mylogger - ERROR - Exception: 
NoneType: None
2023-11-22 08:07:30,784 - asyncio - ERROR - Task exception was never retrieved
future: <Task finished name='Task-3065' coro=<Client._gather.<locals>.wait() done, defined at /home/swx/miniconda3/envs/present_weather/lib/python3.12/site-packages/distributed/client.py:2209> exception=AllExit()>
Traceback (most recent call last):
  File "/home/swx/miniconda3/envs/present_weather/lib/python3.12/site-packages/distributed/client.py", line 2218, in wait
    raise AllExit()
distributed.client.AllExit
2023-11-22 08:07:30,825 - asyncio - ERROR - Task exception was never retrieved
future: <Task finished name='Task-3055' coro=<Client._gather.<locals>.wait() done, defined at /home/swx/miniconda3/envs/present_weather/lib/python3.12/site-packages/distributed/client.py:2209> exception=AllExit()>
Traceback (most recent call last):
  File "/home/swx/miniconda3/envs/present_weather/lib/python3.12/site-packages/distributed/client.py", line 2218, in wait
    raise AllExit()
distributed.client.AllExit
2023-11-22 08:07:30,834 - asyncio - ERROR - Task exception was never retrieved
future: <Task finished name='Task-3039' coro=<Client._gather.<locals>.wait() done, defined at /home/swx/miniconda3/envs/present_weather/lib/python3.12/site-packages/distributed/client.py:2209> exception=AllExit()>
Traceback (most recent call last):
  File "/home/swx/miniconda3/envs/present_weather/lib/python3.12/site-packages/distributed/client.py", line 2218, in wait
    raise AllExit()
distributed.client.AllExit
2023-11-22 08:07:30,839 - asyncio - ERROR - Task exception was never retrieved
future: <Task finished name='Task-3062' coro=<Client._gather.<locals>.wait() done, defined at /home/swx/miniconda3/envs/present_weather/lib/python3.12/site-packages/distributed/client.py:2209> exception=AllExit()>
Traceback (most recent call last):
  File "/home/swx/miniconda3/envs/present_weather/lib/python3.12/site-packages/distributed/client.py", line 2218, in wait
    raise AllExit()
distributed.client.AllExit
2023-11-22 08:07:30,841 - asyncio - ERROR - Task exception was never retrieved
future: <Task finished name='Task-3057' coro=<Client._gather.<locals>.wait() done, defined at /home/swx/miniconda3/envs/present_weather/lib/python3.12/site-packages/distributed/client.py:2209> exception=AllExit()>
Traceback (most recent call last):
  File "/home/swx/miniconda3/envs/present_weather/lib/python3.12/site-packages/distributed/client.py", line 2218, in wait
    raise AllExit()
distributed.client.AllExit
2023-11-22 08:07:30,846 - asyncio - ERROR - Task exception was never retrieved
future: <Task finished name='Task-3058' coro=<Client._gather.<locals>.wait() done, defined at /home/swx/miniconda3/envs/present_weather/lib/python3.12/site-packages/distributed/client.py:2209> exception=AllExit()>
Traceback (most recent call last):
  File "/home/swx/miniconda3/envs/present_weather/lib/python3.12/site-packages/distributed/client.py", line 2218, in wait
    raise AllExit()
distributed.client.AllExit
2023-11-22 08:07:30,859 - asyncio - ERROR - Task exception was never retrieved
future: <Task finished name='Task-3047' coro=<Client._gather.<locals>.wait() done, defined at /home/swx/miniconda3/envs/present_weather/lib/python3.12/site-packages/distributed/client.py:2209> exception=AllExit()>
Traceback (most recent call last):
  File "/home/swx/miniconda3/envs/present_weather/lib/python3.12/site-packages/distributed/client.py", line 2218, in wait
    raise AllExit()
distributed.client.AllExit
2023-11-22 08:07:30,870 - asyncio - ERROR - Task exception was never retrieved
future: <Task finished name='Task-3051' coro=<Client._gather.<locals>.wait() done, defined at /home/swx/miniconda3/envs/present_weather/lib/python3.12/site-packages/distributed/client.py:2209> exception=AllExit()>
Traceback (most recent call last):
  File "/home/swx/miniconda3/envs/present_weather/lib/python3.12/site-packages/distributed/client.py", line 2218, in wait
    raise AllExit()
distributed.client.AllExit
2023-11-22 08:07:30,872 - asyncio - ERROR - Task exception was never retrieved
future: <Task finished name='Task-3040' coro=<Client._gather.<locals>.wait() done, defined at /home/swx/miniconda3/envs/present_weather/lib/python3.12/site-packages/distributed/client.py:2209> exception=AllExit()>
Traceback (most recent call last):
  File "/home/swx/miniconda3/envs/present_weather/lib/python3.12/site-packages/distributed/client.py", line 2218, in wait
    raise AllExit()
distributed.client.AllExit
2023-11-22 08:07:30,874 - asyncio - ERROR - Task exception was never retrieved
future: <Task finished name='Task-3064' coro=<Client._gather.<locals>.wait() done, defined at /home/swx/miniconda3/envs/present_weather/lib/python3.12/site-packages/distributed/client.py:2209> exception=AllExit()>
Traceback (most recent call last):
  File "/home/swx/miniconda3/envs/present_weather/lib/python3.12/site-packages/distributed/client.py", line 2218, in wait
    raise AllExit()
distributed.client.AllExit
2023-11-22 08:07:30,877 - asyncio - ERROR - Task exception was never retrieved
future: <Task finished name='Task-3034' coro=<Client._gather.<locals>.wait() done, defined at /home/swx/miniconda3/envs/present_weather/lib/python3.12/site-packages/distributed/client.py:2209> exception=AllExit()>
Traceback (most recent call last):
  File "/home/swx/miniconda3/envs/present_weather/lib/python3.12/site-packages/distributed/client.py", line 2218, in wait
    raise AllExit()
distributed.client.AllExit
2023-11-22 08:07:30,889 - asyncio - ERROR - Task exception was never retrieved
future: <Task finished name='Task-3037' coro=<Client._gather.<locals>.wait() done, defined at /home/swx/miniconda3/envs/present_weather/lib/python3.12/site-packages/distributed/client.py:2209> exception=AllExit()>
Traceback (most recent call last):
  File "/home/swx/miniconda3/envs/present_weather/lib/python3.12/site-packages/distributed/client.py", line 2218, in wait
    raise AllExit()
distributed.client.AllExit
2023-11-22 08:07:30,891 - asyncio - ERROR - Task exception was never retrieved
future: <Task finished name='Task-3033' coro=<Client._gather.<locals>.wait() done, defined at /home/swx/miniconda3/envs/present_weather/lib/python3.12/site-packages/distributed/client.py:2209> exception=AllExit()>
Traceback (most recent call last):
  File "/home/swx/miniconda3/envs/present_weather/lib/python3.12/site-packages/distributed/client.py", line 2218, in wait
    raise AllExit()
distributed.client.AllExit
2023-11-22 08:07:30,893 - asyncio - ERROR - Task exception was never retrieved
future: <Task finished name='Task-3061' coro=<Client._gather.<locals>.wait() done, defined at /home/swx/miniconda3/envs/present_weather/lib/python3.12/site-packages/distributed/client.py:2209> exception=AllExit()>
Traceback (most recent call last):
  File "/home/swx/miniconda3/envs/present_weather/lib/python3.12/site-packages/distributed/client.py", line 2218, in wait
    raise AllExit()
distributed.client.AllExit
2023-11-22 08:07:30,895 - asyncio - ERROR - Task exception was never retrieved
future: <Task finished name='Task-3054' coro=<Client._gather.<locals>.wait() done, defined at /home/swx/miniconda3/envs/present_weather/lib/python3.12/site-packages/distributed/client.py:2209> exception=AllExit()>
Traceback (most recent call last):
  File "/home/swx/miniconda3/envs/present_weather/lib/python3.12/site-packages/distributed/client.py", line 2218, in wait
    raise AllExit()
distributed.client.AllExit
2023-11-22 08:07:30,897 - asyncio - ERROR - Task exception was never retrieved
future: <Task finished name='Task-3049' coro=<Client._gather.<locals>.wait() done, defined at /home/swx/miniconda3/envs/present_weather/lib/python3.12/site-packages/distributed/client.py:2209> exception=AllExit()>
Traceback (most recent call last):
  File "/home/swx/miniconda3/envs/present_weather/lib/python3.12/site-packages/distributed/client.py", line 2218, in wait
    raise AllExit()
distributed.client.AllExit
2023-11-22 08:07:30,904 - asyncio - ERROR - Task exception was never retrieved
future: <Task finished name='Task-3050' coro=<Client._gather.<locals>.wait() done, defined at /home/swx/miniconda3/envs/present_weather/lib/python3.12/site-packages/distributed/client.py:2209> exception=AllExit()>
Traceback (most recent call last):
  File "/home/swx/miniconda3/envs/present_weather/lib/python3.12/site-packages/distributed/client.py", line 2218, in wait
    raise AllExit()
distributed.client.AllExit
2023-11-22 08:07:30,905 - asyncio - ERROR - Task exception was never retrieved
future: <Task finished name='Task-3046' coro=<Client._gather.<locals>.wait() done, defined at /home/swx/miniconda3/envs/present_weather/lib/python3.12/site-packages/distributed/client.py:2209> exception=AllExit()>
Traceback (most recent call last):
  File "/home/swx/miniconda3/envs/present_weather/lib/python3.12/site-packages/distributed/client.py", line 2218, in wait
    raise AllExit()
distributed.client.AllExit
2023-11-22 08:07:30,906 - asyncio - ERROR - Task exception was never retrieved
future: <Task finished name='Task-3042' coro=<Client._gather.<locals>.wait() done, defined at /home/swx/miniconda3/envs/present_weather/lib/python3.12/site-packages/distributed/client.py:2209> exception=AllExit()>
Traceback (most recent call last):
  File "/home/swx/miniconda3/envs/present_weather/lib/python3.12/site-packages/distributed/client.py", line 2218, in wait
    raise AllExit()
distributed.client.AllExit
2023-11-22 08:07:30,921 - asyncio - ERROR - Task exception was never retrieved
future: <Task finished name='Task-3043' coro=<Client._gather.<locals>.wait() done, defined at /home/swx/miniconda3/envs/present_weather/lib/python3.12/site-packages/distributed/client.py:2209> exception=AllExit()>
Traceback (most recent call last):
  File "/home/swx/miniconda3/envs/present_weather/lib/python3.12/site-packages/distributed/client.py", line 2218, in wait
    raise AllExit()
distributed.client.AllExit
2023-11-22 08:07:30,923 - asyncio - ERROR - Task exception was never retrieved
future: <Task finished name='Task-3038' coro=<Client._gather.<locals>.wait() done, defined at /home/swx/miniconda3/envs/present_weather/lib/python3.12/site-packages/distributed/client.py:2209> exception=AllExit()>
Traceback (most recent call last):
  File "/home/swx/miniconda3/envs/present_weather/lib/python3.12/site-packages/distributed/client.py", line 2218, in wait
    raise AllExit()
distributed.client.AllExit
2023-11-22 08:07:30,927 - asyncio - ERROR - Task exception was never retrieved
future: <Task finished name='Task-3035' coro=<Client._gather.<locals>.wait() done, defined at /home/swx/miniconda3/envs/present_weather/lib/python3.12/site-packages/distributed/client.py:2209> exception=AllExit()>
Traceback (most recent call last):
  File "/home/swx/miniconda3/envs/present_weather/lib/python3.12/site-packages/distributed/client.py", line 2218, in wait
    raise AllExit()
distributed.client.AllExit
2023-11-22 08:07:30,961 - asyncio - ERROR - Task exception was never retrieved
future: <Task finished name='Task-3036' coro=<Client._gather.<locals>.wait() done, defined at /home/swx/miniconda3/envs/present_weather/lib/python3.12/site-packages/distributed/client.py:2209> exception=AllExit()>
Traceback (most recent call last):
  File "/home/swx/miniconda3/envs/present_weather/lib/python3.12/site-packages/distributed/client.py", line 2218, in wait
    raise AllExit()
distributed.client.AllExit
2023-11-22 08:07:30,964 - asyncio - ERROR - Task exception was never retrieved
future: <Task finished name='Task-3032' coro=<Client._gather.<locals>.wait() done, defined at /home/swx/miniconda3/envs/present_weather/lib/python3.12/site-packages/distributed/client.py:2209> exception=AllExit()>
Traceback (most recent call last):
  File "/home/swx/miniconda3/envs/present_weather/lib/python3.12/site-packages/distributed/client.py", line 2218, in wait
    raise AllExit()
distributed.client.AllExit
2023-11-22 08:07:30,974 - asyncio - ERROR - Task exception was never retrieved
future: <Task finished name='Task-3059' coro=<Client._gather.<locals>.wait() done, defined at /home/swx/miniconda3/envs/present_weather/lib/python3.12/site-packages/distributed/client.py:2209> exception=AllExit()>
Traceback (most recent call last):
  File "/home/swx/miniconda3/envs/present_weather/lib/python3.12/site-packages/distributed/client.py", line 2218, in wait
    raise AllExit()
distributed.client.AllExit
2023-11-22 08:07:30,977 - asyncio - ERROR - Task exception was never retrieved
future: <Task finished name='Task-3060' coro=<Client._gather.<locals>.wait() done, defined at /home/swx/miniconda3/envs/present_weather/lib/python3.12/site-packages/distributed/client.py:2209> exception=AllExit()>
Traceback (most recent call last):
  File "/home/swx/miniconda3/envs/present_weather/lib/python3.12/site-packages/distributed/client.py", line 2218, in wait
    raise AllExit()
distributed.client.AllExit
2023-11-22 08:07:30,979 - asyncio - ERROR - Task exception was never retrieved
future: <Task finished name='Task-3056' coro=<Client._gather.<locals>.wait() done, defined at /home/swx/miniconda3/envs/present_weather/lib/python3.12/site-packages/distributed/client.py:2209> exception=AllExit()>
Traceback (most recent call last):
  File "/home/swx/miniconda3/envs/present_weather/lib/python3.12/site-packages/distributed/client.py", line 2218, in wait
    raise AllExit()
distributed.client.AllExit
2023-11-22 08:07:30,980 - asyncio - ERROR - Task exception was never retrieved
future: <Task finished name='Task-3052' coro=<Client._gather.<locals>.wait() done, defined at /home/swx/miniconda3/envs/present_weather/lib/python3.12/site-packages/distributed/client.py:2209> exception=AllExit()>
Traceback (most recent call last):
  File "/home/swx/miniconda3/envs/present_weather/lib/python3.12/site-packages/distributed/client.py", line 2218, in wait
    raise AllExit()
distributed.client.AllExit
2023-11-22 08:07:30,982 - asyncio - ERROR - Task exception was never retrieved
future: <Task finished name='Task-3053' coro=<Client._gather.<locals>.wait() done, defined at /home/swx/miniconda3/envs/present_weather/lib/python3.12/site-packages/distributed/client.py:2209> exception=AllExit()>
Traceback (most recent call last):
  File "/home/swx/miniconda3/envs/present_weather/lib/python3.12/site-packages/distributed/client.py", line 2218, in wait
    raise AllExit()
distributed.client.AllExit
2023-11-22 08:07:30,992 - asyncio - ERROR - Task exception was never retrieved
future: <Task finished name='Task-3048' coro=<Client._gather.<locals>.wait() done, defined at /home/swx/miniconda3/envs/present_weather/lib/python3.12/site-packages/distributed/client.py:2209> exception=AllExit()>
Traceback (most recent call last):
  File "/home/swx/miniconda3/envs/present_weather/lib/python3.12/site-packages/distributed/client.py", line 2218, in wait
    raise AllExit()
distributed.client.AllExit
2023-11-22 08:07:31,000 - asyncio - ERROR - Task exception was never retrieved
future: <Task finished name='Task-3044' coro=<Client._gather.<locals>.wait() done, defined at /home/swx/miniconda3/envs/present_weather/lib/python3.12/site-packages/distributed/client.py:2209> exception=AllExit()>
Traceback (most recent call last):
  File "/home/swx/miniconda3/envs/present_weather/lib/python3.12/site-packages/distributed/client.py", line 2218, in wait
    raise AllExit()
distributed.client.AllExit
2023-11-22 08:07:31,002 - asyncio - ERROR - Task exception was never retrieved
future: <Task finished name='Task-3045' coro=<Client._gather.<locals>.wait() done, defined at /home/swx/miniconda3/envs/present_weather/lib/python3.12/site-packages/distributed/client.py:2209> exception=AllExit()>
Traceback (most recent call last):
  File "/home/swx/miniconda3/envs/present_weather/lib/python3.12/site-packages/distributed/client.py", line 2218, in wait
    raise AllExit()
distributed.client.AllExit
2023-11-22 08:07:31,005 - asyncio - ERROR - Task exception was never retrieved
future: <Task finished name='Task-3041' coro=<Client._gather.<locals>.wait() done, defined at /home/swx/miniconda3/envs/present_weather/lib/python3.12/site-packages/distributed/client.py:2209> exception=AllExit()>
Traceback (most recent call last):
  File "/home/swx/miniconda3/envs/present_weather/lib/python3.12/site-packages/distributed/client.py", line 2218, in wait
    raise AllExit()
distributed.client.AllExit
2023-11-22 08:19:13,165 - root - INFO - Total elapsed time: 0:16:09.766999
